<sdf version='1.7'>
  <world name='default'>
    <scene>
      <sky>
        <clouds>
          <speed>12</speed>
        </clouds>
      </sky>
      <ambient>0.95 0.95 0.95 1</ambient>
      <background>0.3 0.3 0.3 1</background>
      <shadows>1</shadows>
    </scene>
    <light name='sun' type='directional'>
      <cast_shadows>1</cast_shadows>
      <pose>0 0 10 0 -0 0</pose>
      <diffuse>0.8 0.8 0.8 1</diffuse>
      <specular>0.2 0.2 0.2 1</specular>
      <attenuation>
        <range>1000</range>
        <constant>0.9</constant>
        <linear>0.01</linear>
        <quadratic>0.001</quadratic>
      </attenuation>
      <direction>-0.5 0.1 -0.9</direction>
      <spot>
        <inner_angle>0</inner_angle>
        <outer_angle>0</outer_angle>
        <falloff>0</falloff>
      </spot>
    </light>
    <model name='ksql_ground'>
      <pose>0 0 -3.5 0 -0 0</pose>
      <static>1</static>
      <link name='body'>
        <visual name='visual'>
          <geometry>
            <mesh>
              <uri>model://ksql_airport/media/SanCarlosAirport_Terrain.DAE</uri>
            </mesh>
          </geometry>
        </visual>
        <collision name='collision'>
          <geometry>
            <mesh>
              <uri>model://ksql_airport/media/SanCarlosAirport_Terrain.DAE</uri>
            </mesh>
          </geometry>
          <max_contacts>10</max_contacts>
          <surface>
            <contact>
              <ode/>
            </contact>
            <bounce/>
            <friction>
              <torsional>
                <ode/>
              </torsional>
              <ode/>
            </friction>
          </surface>
        </collision>
        <self_collide>0</self_collide>
        <enable_wind>0</enable_wind>
        <kinematic>0</kinematic>
      </link>
      <link name='buildings'>
        <visual name='visual'>
          <geometry>
            <mesh>
              <uri>model://ksql_airport/media/SanCarlosAirport_Buildings.DAE</uri>
            </mesh>
          </geometry>
        </visual>
        <collision name='collision'>
          <geometry>
            <mesh>
              <uri>model://ksql_airport/media/SanCarlosAirport_Buildings.DAE</uri>
            </mesh>
          </geometry>
          <max_contacts>10</max_contacts>
          <surface>
            <contact>
              <ode/>
            </contact>
            <bounce/>
            <friction>
              <torsional>
                <ode/>
              </torsional>
              <ode/>
            </friction>
          </surface>
        </collision>
        <self_collide>0</self_collide>
        <enable_wind>0</enable_wind>
        <kinematic>0</kinematic>
      </link>
    </model>
    <spherical_coordinates>
      <surface_model>EARTH_WGS84</surface_model>
      <latitude_deg>37.5236</latitude_deg>
      <longitude_deg>-122.255</longitude_deg>
      <elevation>1.7</elevation>
      <heading_deg>0</heading_deg>
    </spherical_coordinates>
    <physics name='default_physics' default='0' type='ode'>
      <ode>
        <solver>
          <type>quick</type>
          <iters>10</iters>
          <sor>1.3</sor>
          <use_dynamic_moi_rescaling>0</use_dynamic_moi_rescaling>
        </solver>
        <constraints>
          <cfm>0</cfm>
          <erp>0.2</erp>
          <contact_max_correcting_vel>100</contact_max_correcting_vel>
          <contact_surface_layer>0.001</contact_surface_layer>
        </constraints>
      </ode>
      <max_step_size>0.004</max_step_size>
      <real_time_factor>1</real_time_factor>
      <real_time_update_rate>250</real_time_update_rate>
    </physics>
    <gravity>0 0 -9.8</gravity>
    <magnetic_field>6e-06 2.3e-05 -4.2e-05</magnetic_field>
    <atmosphere type='adiabatic'/>
    <physics type='ode'>
      <max_step_size>0.001</max_step_size>
      <real_time_factor>1</real_time_factor>
      <real_time_update_rate>1000</real_time_update_rate>
    </physics>
    <scene>
      <ambient>0.4 0.4 0.4 1</ambient>
      <background>0.7 0.7 0.7 1</background>
      <shadows>1</shadows>
    </scene>
    <wind/>
    <spherical_coordinates>
      <surface_model>EARTH_WGS84</surface_model>
      <latitude_deg>0</latitude_deg>
      <longitude_deg>0</longitude_deg>
      <elevation>0</elevation>
      <heading_deg>0</heading_deg>
    </spherical_coordinates>
    <model name='matrice_100'>
      <pose>-0.204049 0.363196 0.2 0 -0 0</pose>
      <self_collide>0</self_collide>
      <static>0</static>
      <link name='fuselage'>
        <inertial>
          <mass>2</mass>
          <inertia>
            <ixx>0.0216667</ixx>
            <iyy>0.0216667</iyy>
            <izz>0.04</izz>
            <ixy>0</ixy>
            <ixz>0</ixz>
            <iyz>0</iyz>
          </inertia>
          <pose>0 0 0 0 -0 0</pose>
        </inertial>
        <gravity>1</gravity>
        <self_collide>0</self_collide>
        <velocity_decay/>
        <visual name='fuselage_visual'>
          <geometry>
            <mesh>
              <scale>1 1 1</scale>
              <uri>model://matrice_100/meshes/Matrice_100.dae</uri>
            </mesh>
          </geometry>
        </visual>
        <collision name='fuselage_collision'>
          <pose>0 0 -0.025 0 -0 0</pose>
          <geometry>
            <box>
              <size>0.459619 0.459619 0.25</size>
            </box>
          </geometry>
          <surface>
            <contact>
              <ode>
                <min_depth>0.001</min_depth>
                <max_vel>0</max_vel>
              </ode>
            </contact>
            <friction>
              <ode/>
              <torsional>
                <ode/>
              </torsional>
            </friction>
            <bounce/>
          </surface>
          <max_contacts>10</max_contacts>
        </collision>
        <enable_wind>0</enable_wind>
        <kinematic>0</kinematic>
      </link>
      <link name='rotor_0'>
        <gravity>1</gravity>
        <self_collide>0</self_collide>
        <velocity_decay/>
        <pose>0.22981 -0.22981 0.06 0 -0 0</pose>
        <inertial>
          <mass>0.019</mass>
          <inertia>
            <ixx>6.34917e-07</ixx>
            <iyy>4.31078e-05</iyy>
            <izz>4.37396e-05</izz>
            <ixy>0</ixy>
            <ixz>0</ixz>
            <iyz>0</iyz>
          </inertia>
          <pose>0 0 0 0 -0 0</pose>
        </inertial>
        <visual name='rotor_0_visual'>
          <pose>0 0 0 0 -0 0</pose>
          <geometry>
            <mesh>
              <scale>1 1 1</scale>
              <uri>model://matrice_100/meshes/dji_13455_prop_ccw.dae</uri>
            </mesh>
          </geometry>
          <material>
            <script>
              <name>Gazebo/DarkGrey</name>
              <uri>file://media/materials/scripts/gazebo.material</uri>
            </script>
          </material>
        </visual>
        <collision name='rotor_0_collision'>
          <pose>0 0 0 0 -0 0</pose>
          <geometry>
            <box>
              <size>0.33 0.02 0.001</size>
            </box>
          </geometry>
          <surface>
            <contact>
              <ode>
                <min_depth>0.001</min_depth>
                <max_vel>0</max_vel>
              </ode>
            </contact>
            <friction>
              <ode/>
              <torsional>
                <ode/>
              </torsional>
            </friction>
            <bounce/>
          </surface>
          <max_contacts>10</max_contacts>
        </collision>
        <enable_wind>0</enable_wind>
        <kinematic>0</kinematic>
      </link>
      <joint name='rotor_0_joint' type='revolute'>
        <parent>fuselage</parent>
        <child>rotor_0</child>
        <axis>
          <xyz expressed_in='__model__'>0 0 1</xyz>
          <limit>
            <lower>-1e+16</lower>
            <upper>1e+16</upper>
          </limit>
          <dynamics>
            <spring_reference>0</spring_reference>
            <spring_stiffness>0</spring_stiffness>
          </dynamics>
        </axis>
      </joint>
      <plugin name='rotor_0_motor_model' filename='libgazebo_motor_model.so'>
        <robotNamespace/>
        <jointName>rotor_0_joint</jointName>
        <linkName>rotor_0</linkName>
        <turningDirection>ccw</turningDirection>
        <timeConstantUp>0.0125</timeConstantUp>
        <timeConstantDown>0.025</timeConstantDown>
        <maxRotVelocity>1100</maxRotVelocity>
        <motorConstant>8.54858e-06</motorConstant>
        <momentConstant>0.06</momentConstant>
        <commandSubTopic>/gazebo/command/motor_speed</commandSubTopic>
        <motorNumber>0</motorNumber>
        <rotorDragCoefficient>0.000806428</rotorDragCoefficient>
        <rollingMomentCoefficient>1e-06</rollingMomentCoefficient>
        <motorSpeedPubTopic>/motor_speed/0</motorSpeedPubTopic>
        <rotorVelocitySlowdownSim>10</rotorVelocitySlowdownSim>
      </plugin>
      <link name='rotor_1'>
        <gravity>1</gravity>
        <self_collide>0</self_collide>
        <velocity_decay/>
        <pose>-0.22981 0.22981 0.06 0 -0 0</pose>
        <inertial>
          <mass>0.019</mass>
          <inertia>
            <ixx>6.34917e-07</ixx>
            <iyy>4.31078e-05</iyy>
            <izz>4.37396e-05</izz>
            <ixy>0</ixy>
            <ixz>0</ixz>
            <iyz>0</iyz>
          </inertia>
          <pose>0 0 0 0 -0 0</pose>
        </inertial>
        <visual name='rotor_1_visual'>
          <pose>0 0 0 0 -0 0</pose>
          <geometry>
            <mesh>
              <scale>1 1 1</scale>
              <uri>model://matrice_100/meshes/dji_13455_prop_ccw.dae</uri>
            </mesh>
          </geometry>
          <material>
            <script>
              <name>Gazebo/DarkGrey</name>
              <uri>file://media/materials/scripts/gazebo.material</uri>
            </script>
          </material>
        </visual>
        <collision name='rotor_1_collision'>
          <pose>0 0 0 0 -0 0</pose>
          <geometry>
            <box>
              <size>0.33 0.02 0.001</size>
            </box>
          </geometry>
          <surface>
            <contact>
              <ode>
                <min_depth>0.001</min_depth>
                <max_vel>0</max_vel>
              </ode>
            </contact>
            <friction>
              <ode/>
              <torsional>
                <ode/>
              </torsional>
            </friction>
            <bounce/>
          </surface>
          <max_contacts>10</max_contacts>
        </collision>
        <enable_wind>0</enable_wind>
        <kinematic>0</kinematic>
      </link>
      <joint name='rotor_1_joint' type='revolute'>
        <parent>fuselage</parent>
        <child>rotor_1</child>
        <axis>
          <xyz expressed_in='__model__'>0 0 1</xyz>
          <limit>
            <lower>-1e+16</lower>
            <upper>1e+16</upper>
          </limit>
          <dynamics>
            <spring_reference>0</spring_reference>
            <spring_stiffness>0</spring_stiffness>
          </dynamics>
        </axis>
      </joint>
      <plugin name='rotor_1_motor_model' filename='libgazebo_motor_model.so'>
        <robotNamespace/>
        <jointName>rotor_1_joint</jointName>
        <linkName>rotor_1</linkName>
        <turningDirection>ccw</turningDirection>
        <timeConstantUp>0.0125</timeConstantUp>
        <timeConstantDown>0.025</timeConstantDown>
        <maxRotVelocity>1100</maxRotVelocity>
        <motorConstant>8.54858e-06</motorConstant>
        <momentConstant>0.06</momentConstant>
        <commandSubTopic>/gazebo/command/motor_speed</commandSubTopic>
        <motorNumber>1</motorNumber>
        <rotorDragCoefficient>0.000806428</rotorDragCoefficient>
        <rollingMomentCoefficient>1e-06</rollingMomentCoefficient>
        <motorSpeedPubTopic>/motor_speed/1</motorSpeedPubTopic>
        <rotorVelocitySlowdownSim>10</rotorVelocitySlowdownSim>
      </plugin>
      <link name='rotor_2'>
        <gravity>1</gravity>
        <self_collide>0</self_collide>
        <velocity_decay/>
        <pose>0.22981 0.22981 0.06 0 -0 0</pose>
        <inertial>
          <mass>0.019</mass>
          <inertia>
            <ixx>6.34917e-07</ixx>
            <iyy>4.31078e-05</iyy>
            <izz>4.37396e-05</izz>
            <ixy>0</ixy>
            <ixz>0</ixz>
            <iyz>0</iyz>
          </inertia>
          <pose>0 0 0 0 -0 0</pose>
        </inertial>
        <visual name='rotor_2_visual'>
          <pose>0 0 0 0 -0 0</pose>
          <geometry>
            <mesh>
              <scale>1 1 1</scale>
              <uri>model://matrice_100/meshes/dji_13455_prop_cw.dae</uri>
            </mesh>
          </geometry>
          <material>
            <script>
              <name>Gazebo/DarkGrey</name>
              <uri>file://media/materials/scripts/gazebo.material</uri>
            </script>
          </material>
        </visual>
        <collision name='rotor_2_collision'>
          <pose>0 0 0 0 -0 0</pose>
          <geometry>
            <box>
              <size>0.33 0.02 0.001</size>
            </box>
          </geometry>
          <surface>
            <contact>
              <ode>
                <min_depth>0.001</min_depth>
                <max_vel>0</max_vel>
              </ode>
            </contact>
            <friction>
              <ode/>
              <torsional>
                <ode/>
              </torsional>
            </friction>
            <bounce/>
          </surface>
          <max_contacts>10</max_contacts>
        </collision>
        <enable_wind>0</enable_wind>
        <kinematic>0</kinematic>
      </link>
      <joint name='rotor_2_joint' type='revolute'>
        <parent>fuselage</parent>
        <child>rotor_2</child>
        <axis>
          <xyz expressed_in='__model__'>0 0 1</xyz>
          <limit>
            <lower>-1e+16</lower>
            <upper>1e+16</upper>
          </limit>
          <dynamics>
            <spring_reference>0</spring_reference>
            <spring_stiffness>0</spring_stiffness>
          </dynamics>
        </axis>
      </joint>
      <plugin name='rotor_2_motor_model' filename='libgazebo_motor_model.so'>
        <robotNamespace/>
        <jointName>rotor_2_joint</jointName>
        <linkName>rotor_2</linkName>
        <turningDirection>cw</turningDirection>
        <timeConstantUp>0.0125</timeConstantUp>
        <timeConstantDown>0.025</timeConstantDown>
        <maxRotVelocity>1100</maxRotVelocity>
        <motorConstant>8.54858e-06</motorConstant>
        <momentConstant>0.06</momentConstant>
        <commandSubTopic>/gazebo/command/motor_speed</commandSubTopic>
        <motorNumber>2</motorNumber>
        <rotorDragCoefficient>0.000806428</rotorDragCoefficient>
        <rollingMomentCoefficient>1e-06</rollingMomentCoefficient>
        <motorSpeedPubTopic>/motor_speed/2</motorSpeedPubTopic>
        <rotorVelocitySlowdownSim>10</rotorVelocitySlowdownSim>
      </plugin>
      <link name='rotor_3'>
        <gravity>1</gravity>
        <self_collide>0</self_collide>
        <velocity_decay/>
        <pose>-0.22981 -0.22981 0.06 0 -0 0</pose>
        <inertial>
          <mass>0.019</mass>
          <inertia>
            <ixx>6.34917e-07</ixx>
            <iyy>4.31078e-05</iyy>
            <izz>4.37396e-05</izz>
            <ixy>0</ixy>
            <ixz>0</ixz>
            <iyz>0</iyz>
          </inertia>
          <pose>0 0 0 0 -0 0</pose>
        </inertial>
        <visual name='rotor_3_visual'>
          <pose>0 0 0 0 -0 0</pose>
          <geometry>
            <mesh>
              <scale>1 1 1</scale>
              <uri>model://matrice_100/meshes/dji_13455_prop_cw.dae</uri>
            </mesh>
          </geometry>
          <material>
            <script>
              <name>Gazebo/DarkGrey</name>
              <uri>file://media/materials/scripts/gazebo.material</uri>
            </script>
          </material>
        </visual>
        <collision name='rotor_3_collision'>
          <pose>0 0 0 0 -0 0</pose>
          <geometry>
            <box>
              <size>0.33 0.02 0.001</size>
            </box>
          </geometry>
          <surface>
            <contact>
              <ode>
                <min_depth>0.001</min_depth>
                <max_vel>0</max_vel>
              </ode>
            </contact>
            <friction>
              <ode/>
              <torsional>
                <ode/>
              </torsional>
            </friction>
            <bounce/>
          </surface>
          <max_contacts>10</max_contacts>
        </collision>
        <enable_wind>0</enable_wind>
        <kinematic>0</kinematic>
      </link>
      <joint name='rotor_3_joint' type='revolute'>
        <parent>fuselage</parent>
        <child>rotor_3</child>
        <axis>
          <xyz expressed_in='__model__'>0 0 1</xyz>
          <limit>
            <lower>-1e+16</lower>
            <upper>1e+16</upper>
          </limit>
          <dynamics>
            <spring_reference>0</spring_reference>
            <spring_stiffness>0</spring_stiffness>
          </dynamics>
        </axis>
      </joint>
      <plugin name='rotor_3_motor_model' filename='libgazebo_motor_model.so'>
        <robotNamespace/>
        <jointName>rotor_3_joint</jointName>
        <linkName>rotor_3</linkName>
        <turningDirection>cw</turningDirection>
        <timeConstantUp>0.0125</timeConstantUp>
        <timeConstantDown>0.025</timeConstantDown>
        <maxRotVelocity>1100</maxRotVelocity>
        <motorConstant>8.54858e-06</motorConstant>
        <momentConstant>0.06</momentConstant>
        <commandSubTopic>/gazebo/command/motor_speed</commandSubTopic>
        <motorNumber>3</motorNumber>
        <rotorDragCoefficient>0.000806428</rotorDragCoefficient>
        <rollingMomentCoefficient>1e-06</rollingMomentCoefficient>
        <motorSpeedPubTopic>/motor_speed/3</motorSpeedPubTopic>
        <rotorVelocitySlowdownSim>10</rotorVelocitySlowdownSim>
      </plugin>
      <plugin name='groundtruth_plugin' filename='libgazebo_groundtruth_plugin.so'>
        <robotNamespace/>
      </plugin>
      <plugin name='magnetometer_plugin' filename='libgazebo_magnetometer_plugin.so'>
        <robotNamespace/>
        <pubRate>100</pubRate>
        <noiseDensity>0.0004</noiseDensity>
        <randomWalk>6.4e-06</randomWalk>
        <biasCorrelationTime>600</biasCorrelationTime>
        <magTopic>/mag</magTopic>
      </plugin>
      <plugin name='barometer_plugin' filename='libgazebo_barometer_plugin.so'>
        <robotNamespace/>
        <pubRate>50</pubRate>
        <baroTopic>/baro</baroTopic>
      </plugin>
      <plugin name='mavlink_interface' filename='libgazebo_mavlink_interface.so'>
        <robotNamespace/>
        <imuSubTopic>/imu</imuSubTopic>
        <gpsSubTopic>/gps</gpsSubTopic>
        <mavlink_addr>INADDR_ANY</mavlink_addr>
        <mavlink_udp_port>14560</mavlink_udp_port>
        <serialEnabled>0</serialEnabled>
        <serialDevice>/dev/ttyACM0</serialDevice>
        <baudRate>921600</baudRate>
        <qgc_addr>INADDR_ANY</qgc_addr>
        <qgc_udp_port>14550</qgc_udp_port>
        <hil_mode>0</hil_mode>
        <hil_state_level>0</hil_state_level>
        <opticalFlowSubTopic>/px4flow/link/opticalFlow</opticalFlowSubTopic>
        <lidarSubTopic>/sf10a/link/lidar</lidarSubTopic>
        <enable_lockstep>1</enable_lockstep>
        <use_tcp>1</use_tcp>
        <motorSpeedCommandPubTopic>/gazebo/command/motor_speed</motorSpeedCommandPubTopic>
      </plugin>
      <plugin name='gazebo_imu_plugin' filename='libgazebo_imu_plugin.so'>
        <robotNamespace/>
        <linkName>fuselage</linkName>
        <imuTopic>/imu</imuTopic>
        <gyroscopeNoiseDensity>0.0003394</gyroscopeNoiseDensity>
        <gyroscopeRandomWalk>3.8785e-05</gyroscopeRandomWalk>
        <gyroscopeBiasCorrelationTime>1000.0</gyroscopeBiasCorrelationTime>
        <gyroscopeTurnOnBiasSigma>0.0087</gyroscopeTurnOnBiasSigma>
        <accelerometerNoiseDensity>0.004</accelerometerNoiseDensity>
        <accelerometerRandomWalk>0.006</accelerometerRandomWalk>
        <accelerometerBiasCorrelationTime>300.0</accelerometerBiasCorrelationTime>
        <accelerometerTurnOnBiasSigma>0.196</accelerometerTurnOnBiasSigma>
      </plugin>
    </model>
    <state world_name='default'>
      <sim_time>77 354000000</sim_time>
      <real_time>77 868744297</real_time>
      <wall_time>1677767459 406935805</wall_time>
      <iterations>77354</iterations>
      <model name='ksql_ground'>
        <pose>0 0 -3.5 0 -0 0</pose>
        <scale>1 1 1</scale>
        <link name='body'>
          <pose>0 0 -3.5 0 -0 0</pose>
          <velocity>0 0 0 0 -0 0</velocity>
          <acceleration>0 0 0 0 -0 0</acceleration>
          <wrench>0 0 0 0 -0 0</wrench>
        </link>
        <link name='buildings'>
          <pose>0 0 -3.5 0 -0 0</pose>
          <velocity>0 0 0 0 -0 0</velocity>
          <acceleration>0 0 0 0 -0 0</acceleration>
          <wrench>0 0 0 0 -0 0</wrench>
        </link>
      </model>
      <model name='matrice_100'>
        <pose>-0.198056 0.358473 -0.010585 0.03233 0.040667 0.001132</pose>
        <scale>1 1 1</scale>
        <link name='fuselage'>
          <pose>-0.198056 0.358473 -0.010585 0.03233 0.040667 0.001132</pose>
          <velocity>4.6e-05 0.000134 -5e-06 -0.000894 0.000306 4.6e-05</velocity>
          <acceleration>0.001968 0.001703 -0.000274 -0.011293 0.013189 0.001293</acceleration>
          <wrench>0.003937 0.003406 -0.000548 0 -0 0</wrench>
        </link>
        <link name='rotor_0'>
          <pose>0.033962 0.127106 0.032569 0.032324 0.040672 0.000983</pose>
          <velocity>7.4e-05 0.000187 0.000129 -0.000879 0.000296 4.5e-05</velocity>
          <acceleration>0.006775 0.005532 -0.001936 0.00386 0.003115 -0.000197</acceleration>
          <wrench>0.000129 0.000105 -3.7e-05 0 -0 0</wrench>
        </link>
        <link name='rotor_1'>
          <pose>-0.425194 0.585966 0.0661 0.032324 0.040672 0.000983</pose>
          <velocity>5.8e-05 0.000191 -0.000138 -0.000879 0.000295 4.5e-05</velocity>
          <acceleration>0.002501 0.001084 0.000957 0.003608 0.002654 -0.000192</acceleration>
          <wrench>4.8e-05 2.1e-05 1.8e-05 0 -0 0</wrench>
        </link>
        <link name='rotor_2'>
          <pose>0.034046 0.586486 0.047414 0.032325 0.040672 0.000983</pose>
          <velocity>5.3e-05 0.0002 -0.000274 -0.000879 0.000295 4.5e-05</velocity>
          <acceleration>0.002397 0.005403 -1.3e-05 0.003358 0.00228 -0.000185</acceleration>
          <wrench>4.6e-05 0.000103 -0 0 -0 0</wrench>
        </link>
        <link name='rotor_3'>
          <pose>-0.425278 0.126586 0.051255 0.032325 0.040672 0.000983</pose>
          <velocity>7.9e-05 0.000178 0.000265 -0.000879 0.000295 4.5e-05</velocity>
          <acceleration>0.006683 0.001004 -0.00102 0.003899 0.001763 -0.000243</acceleration>
          <wrench>0.000127 1.9e-05 -1.9e-05 0 -0 0</wrench>
        </link>
      </model>
      <light name='sun'>
        <pose>0 0 10 0 -0 0</pose>
      </light>
    </state>
    <gui fullscreen='0'>
      <camera name='user_camera'>
        <pose>3.02638 0.212814 9.55361 0 1.18764 -3.03499</pose>
        <view_controller>orbit</view_controller>
        <projection_type>perspective</projection_type>
      </camera>
    </gui>
  </world>
</sdf>
